Workbook
Name Клиенты: [1]!ТабКлиенты[name]
Name Клиенты: [1]!ТабКлиенты[name]
Name Клиенты: ТабКлиенты[name]

Sheet Маршрут
B1: 47.1193, 37.5172 | C1: =IFERROR(REPLACE(B1,SEARCH(",",B1),2,"%2C"),"") -> 47.1193%2C37.5172
B2: 47.1281, 37.5732 | C2: =IFERROR(REPLACE(B2,SEARCH(",",B2),2,"%2C"),"") -> 47.1281%2C37.5732
B3: 47.1149, 37.5127 | C3: =IFERROR(REPLACE(B3,SEARCH(",",B3),2,"%2C"),"") -> 47.1149%2C37.5127
B4: 47.0898, 37.5062 | C4: =IFERROR(REPLACE(B4,SEARCH(",",B4),2,"%2C"),"") -> 47.0898%2C37.5062
B5: 47.087079, 37.519275 | C5: =IFERROR(REPLACE(B5,SEARCH(",",B5),2,"%2C"),"") -> 47.087079%2C37.519275
C6: =IFERROR(REPLACE(B6,SEARCH(",",B6),2,"%2C"),"")
C7: =IFERROR(REPLACE(B7,SEARCH(",",B7),2,"%2C"),"")
C8: =IFERROR(REPLACE(B8,SEARCH(",",B8),2,"%2C"),"")
C9: =IFERROR(REPLACE(B9,SEARCH(",",B9),2,"%2C"),"")
C10: =IFERROR(REPLACE(B10,SEARCH(",",B10),2,"%2C"),"")
C11: =IFERROR(REPLACE(B11,SEARCH(",",B11),2,"%2C"),"")
C12: =IFERROR(REPLACE(B12,SEARCH(",",B12),2,"%2C"),"")
C13: =IFERROR(REPLACE(B13,SEARCH(",",B13),2,"%2C"),"")
C14: =IFERROR(REPLACE(B14,SEARCH(",",B14),2,"%2C"),"")
C15: =IFERROR(REPLACE(B15,SEARCH(",",B15),2,"%2C"),"") | D15: ="https://yandex.ru/maps/?mode=routes&rtext="&C1&"~"&C2&"~"&C3&"~"&C4&"~"&C5&"~"&C6&"~"&C7&"~"&C8&"~"&C9&"~"&C10&"~"&C11&"~"&C12&"~"&C13&"~"&C14&"~"&C15&"~"&C16&"~"&C17&"~"&C18&"~"&C19&"~"&C20&"~"&C21 -> https://yandex.ru/maps/?mode=routes&rtext=47.1193%2C37.5172~47.1281%2C37.5732~47.1149%2C37.5127~47.0898%2C37.5062~47.087079%2C37.519275~~~~~~~~~~~~~~~~
C16: =IFERROR(REPLACE(B16,SEARCH(",",B16),2,"%2C"),"")
C17: =IFERROR(REPLACE(B17,SEARCH(",",B17),2,"%2C"),"")
C18: =IFERROR(REPLACE(B18,SEARCH(",",B18),2,"%2C"),"")
C19: =IFERROR(REPLACE(B19,SEARCH(",",B19),2,"%2C"),"")
C20: =IFERROR(REPLACE(B20,SEARCH(",",B20),2,"%2C"),"")
C21: =IFERROR(REPLACE(B21,SEARCH(",",B21),2,"%2C"),"")

Sheet Доставка
B1: Дата | C1: name | D1: phone | E1: address | F1: GPS | G1: Время | H1: Summ | I1: № Заказов | J1: Мест | K1: Шаблон
A2: 1 | B2: 45391 | C2: Елена пер. Фруктовый | D2: =VLOOKUP($C2,ТабКлиенты[[#All],[name]:[phone]],MATCH(D$1,ТабКлиенты[#Headers],0)-1,0) -> +79497190408 | E2: =VLOOKUP($C2,ТабАдрес[[#All],[Клиент]:[gps]],MATCH(E$1,ТабКлиенты[#Headers],0)-4,0) -> Проектная 10 | F2: =VLOOKUP($C2,ТабАдрес[[#All],[Клиент]:[gps]],MATCH(F$1,ТабКлиенты[#Headers],0)-4,0) -> 47.1281, 37.5732 | H2: 3400 | K2: =A2&". "&C2&CHAR(10)&"Тел.: "&D2&CHAR(10)&"Адрес: "&E2&" ("&I2&")"&CHAR(10)&"https://yandex.ru/maps/?text="&REPLACE(F2,SEARCH(",",F2),2,"%2C")&CHAR(10)&"https://maps.google.com/?daddr="&REPLACE(F2,SEARCH(",",F2),2,"%2C")&CHAR(10)&"К оплате: "&H2&CHAR(10)&"----------------------------------------------------------" -> 1. Елена пер. Фруктовый Тел.: +79497190408 Адрес: Проектная 10 () https://yandex.ru/maps/?text=47.1281%2C37.5732 https://maps.google.com/?daddr=47.1281%2C37.5732 К оплате: 3400 ----------------------------------------------------------
A3: 2 | B3: 45391 | C3: Лариса Кирова | D3: =VLOOKUP($C3,ТабКлиенты[[#All],[name]:[phone]],MATCH(D$1,ТабКлиенты[#Headers],0)-1,0) -> #N/A | E3: =VLOOKUP($C3,ТабАдрес[[#All],[Клиент]:[gps]],MATCH(E$1,ТабКлиенты[#Headers],0)-4,0) -> #N/A | F3: =VLOOKUP($C3,ТабАдрес[[#All],[Клиент]:[gps]],MATCH(F$1,ТабКлиенты[#Headers],0)-4,0) -> #N/A | H3: 0 | K3: =A3&". "&C3&CHAR(10)&"Тел.: "&D3&CHAR(10)&"Адрес: "&E3&" ("&I3&")"&CHAR(10)&"https://yandex.ru/maps/?text="&REPLACE(F3,SEARCH(",",F3),2,"%2C")&CHAR(10)&"https://maps.google.com/?daddr="&REPLACE(F3,SEARCH(",",F3),2,"%2C")&CHAR(10)&"К оплате: "&H3&CHAR(10)&"----------------------------------------------------------" -> #N/A
A4: 3 | B4: 45391 | C4: Галина Агабекова(церковь) | D4: =VLOOKUP($C4,ТабКлиенты[[#All],[name]:[phone]],MATCH(D$1,ТабКлиенты[#Headers],0)-1,0) -> #N/A | E4: =VLOOKUP($C4,ТабАдрес[[#All],[Клиент]:[gps]],MATCH(E$1,ТабКлиенты[#Headers],0)-4,0) -> #N/A | F4: =VLOOKUP($C4,ТабАдрес[[#All],[Клиент]:[gps]],MATCH(F$1,ТабКлиенты[#Headers],0)-4,0) -> #N/A | H4: 6196 | K4: =A4&". "&C4&CHAR(10)&"Тел.: "&D4&CHAR(10)&"Адрес: "&E4&" ("&I4&")"&CHAR(10)&"https://yandex.ru/maps/?text="&REPLACE(F4,SEARCH(",",F4),2,"%2C")&CHAR(10)&"https://maps.google.com/?daddr="&REPLACE(F4,SEARCH(",",F4),2,"%2C")&CHAR(10)&"К оплате: "&H4&CHAR(10)&"----------------------------------------------------------" -> #N/A
A5: 4 | B5: 45391 | C5: Алексей перфоратор | D5: =VLOOKUP($C5,ТабКлиенты[[#All],[name]:[phone]],MATCH(D$1,ТабКлиенты[#Headers],0)-1,0) -> #N/A | E5: =VLOOKUP($C5,ТабАдрес[[#All],[Клиент]:[gps]],MATCH(E$1,ТабКлиенты[#Headers],0)-4,0) -> #N/A | F5: =VLOOKUP($C5,ТабАдрес[[#All],[Клиент]:[gps]],MATCH(F$1,ТабКлиенты[#Headers],0)-4,0) -> #N/A | H5: 0 | K5: =A5&". "&C5&CHAR(10)&"Тел.: "&D5&CHAR(10)&"Адрес: "&E5&" ("&I5&")"&CHAR(10)&"https://yandex.ru/maps/?text="&REPLACE(F5,SEARCH(",",F5),2,"%2C")&CHAR(10)&"https://maps.google.com/?daddr="&REPLACE(F5,SEARCH(",",F5),2,"%2C")&CHAR(10)&"К оплате: "&H5&CHAR(10)&"----------------------------------------------------------" -> #N/A
A6: 5 | B6: 45391 | C6: Кирилл Урицкого 104 | D6: =VLOOKUP($C6,ТабКлиенты[[#All],[name]:[phone]],MATCH(D$1,ТабКлиенты[#Headers],0)-1,0) -> #N/A | E6: =VLOOKUP($C6,ТабАдрес[[#All],[Клиент]:[gps]],MATCH(E$1,ТабКлиенты[#Headers],0)-4,0) -> #N/A | F6: =VLOOKUP($C6,ТабАдрес[[#All],[Клиент]:[gps]],MATCH(F$1,ТабКлиенты[#Headers],0)-4,0) -> #N/A | H6: 3000 | K6: =A6&". "&C6&CHAR(10)&"Тел.: "&D6&CHAR(10)&"Адрес: "&E6&" ("&I6&")"&CHAR(10)&"https://yandex.ru/maps/?text="&REPLACE(F6,SEARCH(",",F6),2,"%2C")&CHAR(10)&"https://maps.google.com/?daddr="&REPLACE(F6,SEARCH(",",F6),2,"%2C")&CHAR(10)&"К оплате: "&H6&CHAR(10)&"----------------------------------------------------------" -> #N/A
A7: 6 | B7: 45391 | C7: Александр 3 База | D7: =VLOOKUP($C7,ТабКлиенты[[#All],[name]:[phone]],MATCH(D$1,ТабКлиенты[#Headers],0)-1,0) -> #N/A | E7: =VLOOKUP($C7,ТабАдрес[[#All],[Клиент]:[gps]],MATCH(E$1,ТабКлиенты[#Headers],0)-4,0) -> #N/A | F7: =VLOOKUP($C7,ТабАдрес[[#All],[Клиент]:[gps]],MATCH(F$1,ТабКлиенты[#Headers],0)-4,0) -> #N/A | H7: 2260 | K7: =A7&". "&C7&CHAR(10)&"Тел.: "&D7&CHAR(10)&"Адрес: "&E7&" ("&I7&")"&CHAR(10)&"https://yandex.ru/maps/?text="&REPLACE(F7,SEARCH(",",F7),2,"%2C")&CHAR(10)&"https://maps.google.com/?daddr="&REPLACE(F7,SEARCH(",",F7),2,"%2C")&CHAR(10)&"К оплате: "&H7&CHAR(10)&"----------------------------------------------------------" -> #N/A
A8: 7 | B8: 45391 | C8: Наталья Вельвет | D8: =VLOOKUP($C8,ТабКлиенты[[#All],[name]:[phone]],MATCH(D$1,ТабКлиенты[#Headers],0)-1,0) -> +79497385016 | E8: =VLOOKUP($C8,ТабАдрес[[#All],[Клиент]:[gps]],MATCH(E$1,ТабКлиенты[#Headers],0)-4,0) -> Шевченко 285А | F8: =VLOOKUP($C8,ТабАдрес[[#All],[Клиент]:[gps]],MATCH(F$1,ТабКлиенты[#Headers],0)-4,0) -> 47.1169, 37.5258 | H8: 1800 | K8: =A8&". "&C8&CHAR(10)&"Тел.: "&D8&CHAR(10)&"Адрес: "&E8&" ("&I8&")"&CHAR(10)&"https://yandex.ru/maps/?text="&REPLACE(F8,SEARCH(",",F8),2,"%2C")&CHAR(10)&"https://maps.google.com/?daddr="&REPLACE(F8,SEARCH(",",F8),2,"%2C")&CHAR(10)&"К оплате: "&H8&CHAR(10)&"----------------------------------------------------------" -> 7. Наталья Вельвет Тел.: +79497385016 Адрес: Шевченко 285А () https://yandex.ru/maps/?text=47.1169%2C37.5258 https://maps.google.com/?daddr=47.1169%2C37.5258 К оплате: 1800 ----------------------------------------------------------
A9: 1 | B9: 45402 | C9: Митрофанов Евгений | D9: =VLOOKUP($C9,ТабКлиенты[[#All],[name]:[phone]],MATCH(D$1,ТабКлиенты[#Headers],0)-1,0) -> #N/A | E9: =VLOOKUP($C9,ТабАдрес[[#All],[Клиент]:[gps]],MATCH(E$1,ТабКлиенты[#Headers],0)-4,0) -> #N/A | F9: =VLOOKUP($C9,ТабАдрес[[#All],[Клиент]:[gps]],MATCH(F$1,ТабКлиенты[#Headers],0)-4,0) -> #N/A | H9: 6067 | I9: 50 | K9: =A9&". "&C9&CHAR(10)&"Тел.: "&D9&CHAR(10)&"Адрес: "&E9&" ("&I9&")"&CHAR(10)&"https://yandex.ru/maps/?text="&REPLACE(F9,SEARCH(",",F9),2,"%2C")&CHAR(10)&"https://maps.google.com/?daddr="&REPLACE(F9,SEARCH(",",F9),2,"%2C")&CHAR(10)&"К оплате: "&H9&CHAR(10)&"----------------------------------------------------------" -> #N/A
A10: 2 | B10: 45402 | C10: Александр 3 Металлургов | D10: =VLOOKUP($C10,ТабКлиенты[[#All],[name]:[phone]],MATCH(D$1,ТабКлиенты[#Headers],0)-1,0) -> #N/A | E10: =VLOOKUP($C10,ТабАдрес[[#All],[Клиент]:[gps]],MATCH(E$1,ТабКлиенты[#Headers],0)-4,0) -> #N/A | F10: =VLOOKUP($C10,ТабАдрес[[#All],[Клиент]:[gps]],MATCH(F$1,ТабКлиенты[#Headers],0)-4,0) -> #N/A | H10: 0 | I10: 52 | K10: =A10&". "&C10&CHAR(10)&"Тел.: "&D10&CHAR(10)&"Адрес: "&E10&" ("&I10&")"&CHAR(10)&"https://yandex.ru/maps/?text="&REPLACE(F10,SEARCH(",",F10),2,"%2C")&CHAR(10)&"https://maps.google.com/?daddr="&REPLACE(F10,SEARCH(",",F10),2,"%2C")&CHAR(10)&"К оплате: "&H10&CHAR(10)&"----------------------------------------------------------" -> #N/A
A11: 3 | B11: 45402 | C11: Юля Нептун | D11: =VLOOKUP($C11,ТабКлиенты[[#All],[name]:[phone]],MATCH(D$1,ТабКлиенты[#Headers],0)-1,0) -> #N/A | E11: =VLOOKUP($C11,ТабАдрес[[#All],[Клиент]:[gps]],MATCH(E$1,ТабКлиенты[#Headers],0)-4,0) -> #N/A | F11: =VLOOKUP($C11,ТабАдрес[[#All],[Клиент]:[gps]],MATCH(F$1,ТабКлиенты[#Headers],0)-4,0) -> #N/A | H11: 3000 | I11: Витамины | K11: =A11&". "&C11&CHAR(10)&"Тел.: "&D11&CHAR(10)&"Адрес: "&E11&" ("&I11&")"&CHAR(10)&"https://yandex.ru/maps/?text="&REPLACE(F11,SEARCH(",",F11),2,"%2C")&CHAR(10)&"https://maps.google.com/?daddr="&REPLACE(F11,SEARCH(",",F11),2,"%2C")&CHAR(10)&"К оплате: "&H11&CHAR(10)&"----------------------------------------------------------" -> #N/A
A12: 4 | B12: 45402 | C12: Галина Агабекова(церковь) | D12: =VLOOKUP($C12,ТабКлиенты[[#All],[name]:[phone]],MATCH(D$1,ТабКлиенты[#Headers],0)-1,0) -> #N/A | E12: =VLOOKUP($C12,ТабАдрес[[#All],[Клиент]:[gps]],MATCH(E$1,ТабКлиенты[#Headers],0)-4,0) -> #N/A | F12: =VLOOKUP($C12,ТабАдрес[[#All],[Клиент]:[gps]],MATCH(F$1,ТабКлиенты[#Headers],0)-4,0) -> #N/A | H12: 5887 | I12: 53.56 | K12: =A12&". "&C12&CHAR(10)&"Тел.: "&D12&CHAR(10)&"Адрес: "&E12&" ("&I12&")"&CHAR(10)&"https://yandex.ru/maps/?text="&REPLACE(F12,SEARCH(",",F12),2,"%2C")&CHAR(10)&"https://maps.google.com/?daddr="&REPLACE(F12,SEARCH(",",F12),2,"%2C")&CHAR(10)&"К оплате: "&H12&CHAR(10)&"----------------------------------------------------------" -> #N/A
A13: 5 | B13: 45402 | C13: Галина Шевченко 248 | D13: =VLOOKUP($C13,ТабКлиенты[[#All],[name]:[phone]],MATCH(D$1,ТабКлиенты[#Headers],0)-1,0) -> #N/A | E13: =VLOOKUP($C13,ТабАдрес[[#All],[Клиент]:[gps]],MATCH(E$1,ТабКлиенты[#Headers],0)-4,0) -> #N/A | F13: =VLOOKUP($C13,ТабАдрес[[#All],[Клиент]:[gps]],MATCH(F$1,ТабКлиенты[#Headers],0)-4,0) -> #N/A | H13: 0 | I13: 64 | K13: =A13&". "&C13&CHAR(10)&"Тел.: "&D13&CHAR(10)&"Адрес: "&E13&" ("&I13&")"&CHAR(10)&"https://yandex.ru/maps/?text="&REPLACE(F13,SEARCH(",",F13),2,"%2C")&CHAR(10)&"https://maps.google.com/?daddr="&REPLACE(F13,SEARCH(",",F13),2,"%2C")&CHAR(10)&"К оплате: "&H13&CHAR(10)&"----------------------------------------------------------" -> #N/A
A14: 6 | B14: 45402 | C14: ОТ Порт сити | D14: =VLOOKUP($C14,ТабКлиенты[[#All],[name]:[phone]],MATCH(D$1,ТабКлиенты[#Headers],0)-1,0) -> #N/A | E14: =VLOOKUP($C14,ТабАдрес[[#All],[Клиент]:[gps]],MATCH(E$1,ТабКлиенты[#Headers],0)-4,0) -> #N/A | F14: =VLOOKUP($C14,ТабАдрес[[#All],[Клиент]:[gps]],MATCH(F$1,ТабКлиенты[#Headers],0)-4,0) -> #N/A | H14: 2600 | I14: Витамины | K14: =A14&". "&C14&CHAR(10)&"Тел.: "&D14&CHAR(10)&"Адрес: "&E14&" ("&I14&")"&CHAR(10)&"https://yandex.ru/maps/?text="&REPLACE(F14,SEARCH(",",F14),2,"%2C")&CHAR(10)&"https://maps.google.com/?daddr="&REPLACE(F14,SEARCH(",",F14),2,"%2C")&CHAR(10)&"К оплате: "&H14&CHAR(10)&"----------------------------------------------------------" -> #N/A
A15: 7 | B15: 45402 | C15: Оксана 17 цветы | D15: =VLOOKUP($C15,ТабКлиенты[[#All],[name]:[phone]],MATCH(D$1,ТабКлиенты[#Headers],0)-1,0) -> 0 | E15: =VLOOKUP($C15,ТабАдрес[[#All],[Клиент]:[gps]],MATCH(E$1,ТабКлиенты[#Headers],0)-4,0) -> Троицкая 46 | F15: =VLOOKUP($C15,ТабАдрес[[#All],[Клиент]:[gps]],MATCH(F$1,ТабКлиенты[#Headers],0)-4,0) -> 47.1119, 37.5147 | H15: 4100 | I15: Витамины | K15: =A15&". "&C15&CHAR(10)&"Тел.: "&D15&CHAR(10)&"Адрес: "&E15&" ("&I15&")"&CHAR(10)&"https://yandex.ru/maps/?text="&REPLACE(F15,SEARCH(",",F15),2,"%2C")&CHAR(10)&"https://maps.google.com/?daddr="&REPLACE(F15,SEARCH(",",F15),2,"%2C")&CHAR(10)&"К оплате: "&H15&CHAR(10)&"----------------------------------------------------------" -> 7. Оксана 17 цветы Тел.: 0 Адрес: Троицкая 46 (Витамины) https://yandex.ru/maps/?text=47.1119%2C37.5147 https://maps.google.com/?daddr=47.1119%2C37.5147 К оплате: 4100 ----------------------------------------------------------
A16: 8 | B16: 45402 | C16: Елена 17 рынок | D16: =VLOOKUP($C16,ТабКлиенты[[#All],[name]:[phone]],MATCH(D$1,ТабКлиенты[#Headers],0)-1,0) -> #N/A | E16: =VLOOKUP($C16,ТабАдрес[[#All],[Клиент]:[gps]],MATCH(E$1,ТабКлиенты[#Headers],0)-4,0) -> #N/A | F16: =VLOOKUP($C16,ТабАдрес[[#All],[Клиент]:[gps]],MATCH(F$1,ТабКлиенты[#Headers],0)-4,0) -> #N/A | H16: 2400 | I16: Витамины | K16: =A16&". "&C16&CHAR(10)&"Тел.: "&D16&CHAR(10)&"Адрес: "&E16&" ("&I16&")"&CHAR(10)&"https://yandex.ru/maps/?text="&REPLACE(F16,SEARCH(",",F16),2,"%2C")&CHAR(10)&"https://maps.google.com/?daddr="&REPLACE(F16,SEARCH(",",F16),2,"%2C")&CHAR(10)&"К оплате: "&H16&CHAR(10)&"----------------------------------------------------------" -> #N/A
A17: 9 | B17: 45402 | C17: Валера Фагот | D17: =VLOOKUP($C17,ТабКлиенты[[#All],[name]:[phone]],MATCH(D$1,ТабКлиенты[#Headers],0)-1,0) -> #N/A | E17: =VLOOKUP($C17,ТабАдрес[[#All],[Клиент]:[gps]],MATCH(E$1,ТабКлиенты[#Headers],0)-4,0) -> #N/A | F17: =VLOOKUP($C17,ТабАдрес[[#All],[Клиент]:[gps]],MATCH(F$1,ТабКлиенты[#Headers],0)-4,0) -> #N/A | H17: 8700 | I17: Витамины | K17: =A17&". "&C17&CHAR(10)&"Тел.: "&D17&CHAR(10)&"Адрес: "&E17&" ("&I17&")"&CHAR(10)&"https://yandex.ru/maps/?text="&REPLACE(F17,SEARCH(",",F17),2,"%2C")&CHAR(10)&"https://maps.google.com/?daddr="&REPLACE(F17,SEARCH(",",F17),2,"%2C")&CHAR(10)&"К оплате: "&H17&CHAR(10)&"----------------------------------------------------------" -> #N/A
A18: 10 | B18: 45402 | C18: Наталья | D18: =VLOOKUP($C18,ТабКлиенты[[#All],[name]:[phone]],MATCH(D$1,ТабКлиенты[#Headers],0)-1,0) -> #N/A | E18: =VLOOKUP($C18,ТабАдрес[[#All],[Клиент]:[gps]],MATCH(E$1,ТабКлиенты[#Headers],0)-4,0) -> #N/A | F18: =VLOOKUP($C18,ТабАдрес[[#All],[Клиент]:[gps]],MATCH(F$1,ТабКлиенты[#Headers],0)-4,0) -> #N/A | H18: 6300 | I18: Витамины | K18: =A18&". "&C18&CHAR(10)&"Тел.: "&D18&CHAR(10)&"Адрес: "&E18&" ("&I18&")"&CHAR(10)&"https://yandex.ru/maps/?text="&REPLACE(F18,SEARCH(",",F18),2,"%2C")&CHAR(10)&"https://maps.google.com/?daddr="&REPLACE(F18,SEARCH(",",F18),2,"%2C")&CHAR(10)&"К оплате: "&H18&CHAR(10)&"----------------------------------------------------------" -> #N/A
A19: 11 | B19: 45402 | C19: Елена Ларисына | D19: =VLOOKUP($C19,ТабКлиенты[[#All],[name]:[phone]],MATCH(D$1,ТабКлиенты[#Headers],0)-1,0) -> #N/A | E19: =VLOOKUP($C19,ТабАдрес[[#All],[Клиент]:[gps]],MATCH(E$1,ТабКлиенты[#Headers],0)-4,0) -> #N/A | F19: =VLOOKUP($C19,ТабАдрес[[#All],[Клиент]:[gps]],MATCH(F$1,ТабКлиенты[#Headers],0)-4,0) -> #N/A | H19: 0 | I19: 54, 58, 59 | K19: =A19&". "&C19&CHAR(10)&"Тел.: "&D19&CHAR(10)&"Адрес: "&E19&" ("&I19&")"&CHAR(10)&"https://yandex.ru/maps/?text="&REPLACE(F19,SEARCH(",",F19),2,"%2C")&CHAR(10)&"https://maps.google.com/?daddr="&REPLACE(F19,SEARCH(",",F19),2,"%2C")&CHAR(10)&"К оплате: "&H19&CHAR(10)&"----------------------------------------------------------" -> #N/A
A20: 12 | B20: 45402 | C20: Лариса Кирова | D20: =VLOOKUP($C20,ТабКлиенты[[#All],[name]:[phone]],MATCH(D$1,ТабКлиенты[#Headers],0)-1,0) -> #N/A | E20: =VLOOKUP($C20,ТабАдрес[[#All],[Клиент]:[gps]],MATCH(E$1,ТабКлиенты[#Headers],0)-4,0) -> #N/A | F20: =VLOOKUP($C20,ТабАдрес[[#All],[Клиент]:[gps]],MATCH(F$1,ТабКлиенты[#Headers],0)-4,0) -> #N/A | H20: 803 | I20: 49.59 | K20: =A20&". "&C20&CHAR(10)&"Тел.: "&D20&CHAR(10)&"Адрес: "&E20&" ("&I20&")"&CHAR(10)&"https://yandex.ru/maps/?text="&REPLACE(F20,SEARCH(",",F20),2,"%2C")&CHAR(10)&"https://maps.google.com/?daddr="&REPLACE(F20,SEARCH(",",F20),2,"%2C")&CHAR(10)&"К оплате: "&H20&CHAR(10)&"----------------------------------------------------------" -> #N/A
A21: 13 | B21: 45402 | C21: Елена от Ани | D21: =VLOOKUP($C21,ТабКлиенты[[#All],[name]:[phone]],MATCH(D$1,ТабКлиенты[#Headers],0)-1,0) -> #N/A | E21: =VLOOKUP($C21,ТабАдрес[[#All],[Клиент]:[gps]],MATCH(E$1,ТабКлиенты[#Headers],0)-4,0) -> #N/A | F21: =VLOOKUP($C21,ТабАдрес[[#All],[Клиент]:[gps]],MATCH(F$1,ТабКлиенты[#Headers],0)-4,0) -> #N/A | H21: 4600 | I21: Витамины | K21: =A21&". "&C21&CHAR(10)&"Тел.: "&D21&CHAR(10)&"Адрес: "&E21&" ("&I21&")"&CHAR(10)&"https://yandex.ru/maps/?text="&REPLACE(F21,SEARCH(",",F21),2,"%2C")&CHAR(10)&"https://maps.google.com/?daddr="&REPLACE(F21,SEARCH(",",F21),2,"%2C")&CHAR(10)&"К оплате: "&H21&CHAR(10)&"----------------------------------------------------------" -> #N/A
A22: 1 | B22: 45409 | C22: Максим рюкзак | D22: =VLOOKUP($C22,ТабКлиенты[[#All],[name]:[phone]],MATCH(D$1,ТабКлиенты[#Headers],0)-1,0) -> #N/A | E22: =VLOOKUP($C22,ТабАдрес[[#All],[Клиент]:[gps]],MATCH(E$1,ТабКлиенты[#Headers],0)-4,0) -> #N/A | F22: =VLOOKUP($C22,ТабАдрес[[#All],[Клиент]:[gps]],MATCH(F$1,ТабКлиенты[#Headers],0)-4,0) -> #N/A | H22: 1528 | I22: 71 | K22: =A22&". "&C22&CHAR(10)&"Тел.: "&D22&CHAR(10)&"Адрес: "&E22&" ("&I22&")"&CHAR(10)&"https://yandex.ru/maps/?text="&REPLACE(F22,SEARCH(",",F22),2,"%2C")&CHAR(10)&"https://maps.google.com/?daddr="&REPLACE(F22,SEARCH(",",F22),2,"%2C")&CHAR(10)&"К оплате: "&H22&CHAR(10)&"----------------------------------------------------------" -> #N/A
A23: 2 | B23: 45409 | C23: Макс Куприна | D23: =VLOOKUP($C23,ТабКлиенты[[#All],[name]:[phone]],MATCH(D$1,ТабКлиенты[#Headers],0)-1,0) -> #N/A | E23: =VLOOKUP($C23,ТабАдрес[[#All],[Клиент]:[gps]],MATCH(E$1,ТабКлиенты[#Headers],0)-4,0) -> #N/A | F23: =VLOOKUP($C23,ТабАдрес[[#All],[Клиент]:[gps]],MATCH(F$1,ТабКлиенты[#Headers],0)-4,0) -> #N/A | H23: 0 | I23: 67 | K23: =A23&". "&C23&CHAR(10)&"Тел.: "&D23&CHAR(10)&"Адрес: "&E23&" ("&I23&")"&CHAR(10)&"https://yandex.ru/maps/?text="&REPLACE(F23,SEARCH(",",F23),2,"%2C")&CHAR(10)&"https://maps.google.com/?daddr="&REPLACE(F23,SEARCH(",",F23),2,"%2C")&CHAR(10)&"К оплате: "&H23&CHAR(10)&"----------------------------------------------------------" -> #N/A
A24: 3 | B24: 45409 | C24: Константин Маркет | D24: =VLOOKUP($C24,ТабКлиенты[[#All],[name]:[phone]],MATCH(D$1,ТабКлиенты[#Headers],0)-1,0) -> #N/A | E24: =VLOOKUP($C24,ТабАдрес[[#All],[Клиент]:[gps]],MATCH(E$1,ТабКлиенты[#Headers],0)-4,0) -> #N/A | F24: =VLOOKUP($C24,ТабАдрес[[#All],[Клиент]:[gps]],MATCH(F$1,ТабКлиенты[#Headers],0)-4,0) -> #N/A | H24: 0 | I24: 60 | K24: =A24&". "&C24&CHAR(10)&"Тел.: "&D24&CHAR(10)&"Адрес: "&E24&" ("&I24&")"&CHAR(10)&"https://yandex.ru/maps/?text="&REPLACE(F24,SEARCH(",",F24),2,"%2C")&CHAR(10)&"https://maps.google.com/?daddr="&REPLACE(F24,SEARCH(",",F24),2,"%2C")&CHAR(10)&"К оплате: "&H24&CHAR(10)&"----------------------------------------------------------" -> #N/A
A25: 4 | B25: 45409 | C25: Галина Шевченко 248 | D25: =VLOOKUP($C25,ТабКлиенты[[#All],[name]:[phone]],MATCH(D$1,ТабКлиенты[#Headers],0)-1,0) -> #N/A | E25: =VLOOKUP($C25,ТабАдрес[[#All],[Клиент]:[gps]],MATCH(E$1,ТабКлиенты[#Headers],0)-4,0) -> #N/A | F25: =VLOOKUP($C25,ТабАдрес[[#All],[Клиент]:[gps]],MATCH(F$1,ТабКлиенты[#Headers],0)-4,0) -> #N/A | H25: 0 | I25: 64, 75 | K25: =A25&". "&C25&CHAR(10)&"Тел.: "&D25&CHAR(10)&"Адрес: "&E25&" ("&I25&")"&CHAR(10)&"https://yandex.ru/maps/?text="&REPLACE(F25,SEARCH(",",F25),2,"%2C")&CHAR(10)&"https://maps.google.com/?daddr="&REPLACE(F25,SEARCH(",",F25),2,"%2C")&CHAR(10)&"К оплате: "&H25&CHAR(10)&"----------------------------------------------------------" -> #N/A
A26: 5 | B26: 45409 | C26: Галина Агабекова(церковь) | D26: =VLOOKUP($C26,ТабКлиенты[[#All],[name]:[phone]],MATCH(D$1,ТабКлиенты[#Headers],0)-1,0) -> #N/A | E26: =VLOOKUP($C26,ТабАдрес[[#All],[Клиент]:[gps]],MATCH(E$1,ТабКлиенты[#Headers],0)-4,0) -> #N/A | F26: =VLOOKUP($C26,ТабАдрес[[#All],[Клиент]:[gps]],MATCH(F$1,ТабКлиенты[#Headers],0)-4,0) -> #N/A | H26: 0 | I26: 66 | K26: =A26&". "&C26&CHAR(10)&"Тел.: "&D26&CHAR(10)&"Адрес: "&E26&" ("&I26&")"&CHAR(10)&"https://yandex.ru/maps/?text="&REPLACE(F26,SEARCH(",",F26),2,"%2C")&CHAR(10)&"https://maps.google.com/?daddr="&REPLACE(F26,SEARCH(",",F26),2,"%2C")&CHAR(10)&"К оплате: "&H26&CHAR(10)&"----------------------------------------------------------" -> #N/A
A27: 6 | B27: 45409 | C27: Лариса Кирова | D27: =VLOOKUP($C27,ТабКлиенты[[#All],[name]:[phone]],MATCH(D$1,ТабКлиенты[#Headers],0)-1,0) -> #N/A | E27: =VLOOKUP($C27,ТабАдрес[[#All],[Клиент]:[gps]],MATCH(E$1,ТабКлиенты[#Headers],0)-4,0) -> #N/A | F27: =VLOOKUP($C27,ТабАдрес[[#All],[Клиент]:[gps]],MATCH(F$1,ТабКлиенты[#Headers],0)-4,0) -> #N/A | H27: =2556+472 -> 3028 | I27: 59, 69 | K27: =A27&". "&C27&CHAR(10)&"Тел.: "&D27&CHAR(10)&"Адрес: "&E27&" ("&I27&")"&CHAR(10)&"https://yandex.ru/maps/?text="&REPLACE(F27,SEARCH(",",F27),2,"%2C")&CHAR(10)&"https://maps.google.com/?daddr="&REPLACE(F27,SEARCH(",",F27),2,"%2C")&CHAR(10)&"К оплате: "&H27&CHAR(10)&"----------------------------------------------------------" -> #N/A
A28: 7 | B28: 45409 | C28: Наталья 12 | D28: =VLOOKUP($C28,ТабКлиенты[[#All],[name]:[phone]],MATCH(D$1,ТабКлиенты[#Headers],0)-1,0) -> #N/A | E28: =VLOOKUP($C28,ТабАдрес[[#All],[Клиент]:[gps]],MATCH(E$1,ТабКлиенты[#Headers],0)-4,0) -> #N/A | F28: =VLOOKUP($C28,ТабАдрес[[#All],[Клиент]:[gps]],MATCH(F$1,ТабКлиенты[#Headers],0)-4,0) -> #N/A | H28: 0 | I28: 72 | K28: =A28&". "&C28&CHAR(10)&"Тел.: "&D28&CHAR(10)&"Адрес: "&E28&" ("&I28&")"&CHAR(10)&"https://yandex.ru/maps/?text="&REPLACE(F28,SEARCH(",",F28),2,"%2C")&CHAR(10)&"https://maps.google.com/?daddr="&REPLACE(F28,SEARCH(",",F28),2,"%2C")&CHAR(10)&"К оплате: "&H28&CHAR(10)&"----------------------------------------------------------" -> #N/A
A29: 8 | B29: 45409 | C29: Лена Ларисына | D29: =VLOOKUP($C29,ТабКлиенты[[#All],[name]:[phone]],MATCH(D$1,ТабКлиенты[#Headers],0)-1,0) -> #N/A | E29: =VLOOKUP($C29,ТабАдрес[[#All],[Клиент]:[gps]],MATCH(E$1,ТабКлиенты[#Headers],0)-4,0) -> #N/A | F29: =VLOOKUP($C29,ТабАдрес[[#All],[Клиент]:[gps]],MATCH(F$1,ТабКлиенты[#Headers],0)-4,0) -> #N/A | H29: 0 | I29: 69 | K29: =A29&". "&C29&CHAR(10)&"Тел.: "&D29&CHAR(10)&"Адрес: "&E29&" ("&I29&")"&CHAR(10)&"https://yandex.ru/maps/?text="&REPLACE(F29,SEARCH(",",F29),2,"%2C")&CHAR(10)&"https://maps.google.com/?daddr="&REPLACE(F29,SEARCH(",",F29),2,"%2C")&CHAR(10)&"К оплате: "&H29&CHAR(10)&"----------------------------------------------------------" -> #N/A
A30: 9 | B30: 45409 | C30: Татьяна Торговая 100 | D30: =VLOOKUP($C30,ТабКлиенты[[#All],[name]:[phone]],MATCH(D$1,ТабКлиенты[#Headers],0)-1,0) -> +79497267699 | E30: =VLOOKUP($C30,ТабАдрес[[#All],[Клиент]:[gps]],MATCH(E$1,ТабКлиенты[#Headers],0)-4,0) -> Торговая 100 | F30: =VLOOKUP($C30,ТабАдрес[[#All],[Клиент]:[gps]],MATCH(F$1,ТабКлиенты[#Headers],0)-4,0) -> 47.1034, 37.5633 | H30: 2200 | I30: Витамины | K30: =A30&". "&C30&CHAR(10)&"Тел.: "&D30&CHAR(10)&"Адрес: "&E30&" ("&I30&")"&CHAR(10)&"https://yandex.ru/maps/?text="&REPLACE(F30,SEARCH(",",F30),2,"%2C")&CHAR(10)&"https://maps.google.com/?daddr="&REPLACE(F30,SEARCH(",",F30),2,"%2C")&CHAR(10)&"К оплате: "&H30&CHAR(10)&"----------------------------------------------------------" -> 9. Татьяна Торговая 100 Тел.: +79497267699 Адрес: Торговая 100 (Витамины) https://yandex.ru/maps/?text=47.1034%2C37.5633 https://maps.google.com/?daddr=47.1034%2C37.5633 К оплате: 2200 ----------------------------------------------------------
A31: 10 | B31: 45409 | C31: Митрофанов Евгений | D31: =VLOOKUP($C31,ТабКлиенты[[#All],[name]:[phone]],MATCH(D$1,ТабКлиенты[#Headers],0)-1,0) -> #N/A | E31: =VLOOKUP($C31,ТабАдрес[[#All],[Клиент]:[gps]],MATCH(E$1,ТабКлиенты[#Headers],0)-4,0) -> #N/A | F31: =VLOOKUP($C31,ТабАдрес[[#All],[Клиент]:[gps]],MATCH(F$1,ТабКлиенты[#Headers],0)-4,0) -> #N/A | H31: 0 | I31: 65 | K31: =A31&". "&C31&CHAR(10)&"Тел.: "&D31&CHAR(10)&"Адрес: "&E31&" ("&I31&")"&CHAR(10)&"https://yandex.ru/maps/?text="&REPLACE(F31,SEARCH(",",F31),2,"%2C")&CHAR(10)&"https://maps.google.com/?daddr="&REPLACE(F31,SEARCH(",",F31),2,"%2C")&CHAR(10)&"К оплате: "&H31&CHAR(10)&"----------------------------------------------------------" -> #N/A
A32: 11 | B32: 45409 | C32: Карина Кравченко 17 | D32: =VLOOKUP($C32,ТабКлиенты[[#All],[name]:[phone]],MATCH(D$1,ТабКлиенты[#Headers],0)-1,0) -> #N/A | E32: =VLOOKUP($C32,ТабАдрес[[#All],[Клиент]:[gps]],MATCH(E$1,ТабКлиенты[#Headers],0)-4,0) -> #N/A | F32: =VLOOKUP($C32,ТабАдрес[[#All],[Клиент]:[gps]],MATCH(F$1,ТабКлиенты[#Headers],0)-4,0) -> #N/A | H32: 200 | I32: 61 | K32: =A32&". "&C32&CHAR(10)&"Тел.: "&D32&CHAR(10)&"Адрес: "&E32&" ("&I32&")"&CHAR(10)&"https://yandex.ru/maps/?text="&REPLACE(F32,SEARCH(",",F32),2,"%2C")&CHAR(10)&"https://maps.google.com/?daddr="&REPLACE(F32,SEARCH(",",F32),2,"%2C")&CHAR(10)&"К оплате: "&H32&CHAR(10)&"----------------------------------------------------------" -> #N/A
A33: 1 | B33: 45416 | C33: григорий(танковый ) | D33: =VLOOKUP($C33,ТабКлиенты[[#All],[name]:[phone]],MATCH(D$1,ТабКлиенты[#Headers],0)-1,0) -> #N/A | E33: =VLOOKUP($C33,ТабАдрес[[#All],[Клиент]:[gps]],MATCH(E$1,ТабКлиенты[#Headers],0)-4,0) -> #N/A | F33: =VLOOKUP($C33,ТабАдрес[[#All],[Клиент]:[gps]],MATCH(F$1,ТабКлиенты[#Headers],0)-4,0) -> #N/A | H33: 0 | I33: 79 | K33: =A33&". "&C33&CHAR(10)&"Тел.: "&D33&CHAR(10)&"Адрес: "&E33&" ("&I33&")"&CHAR(10)&"https://yandex.ru/maps/?text="&REPLACE(F33,SEARCH(",",F33),2,"%2C")&CHAR(10)&"https://maps.google.com/?daddr="&REPLACE(F33,SEARCH(",",F33),2,"%2C")&CHAR(10)&"К оплате: "&H33&CHAR(10)&"----------------------------------------------------------" -> #N/A
A34: 2 | B34: 45416 | C34: Наталья 12 | D34: =VLOOKUP($C34,ТабКлиенты[[#All],[name]:[phone]],MATCH(D$1,ТабКлиенты[#Headers],0)-1,0) -> #N/A | E34: =VLOOKUP($C34,ТабАдрес[[#All],[Клиент]:[gps]],MATCH(E$1,ТабКлиенты[#Headers],0)-4,0) -> #N/A | F34: =VLOOKUP($C34,ТабАдрес[[#All],[Клиент]:[gps]],MATCH(F$1,ТабКлиенты[#Headers],0)-4,0) -> #N/A | H34: 0 | I34: 72 | K34: =A34&". "&C34&CHAR(10)&"Тел.: "&D34&CHAR(10)&"Адрес: "&E34&" ("&I34&")"&CHAR(10)&"https://yandex.ru/maps/?text="&REPLACE(F34,SEARCH(",",F34),2,"%2C")&CHAR(10)&"https://maps.google.com/?daddr="&REPLACE(F34,SEARCH(",",F34),2,"%2C")&CHAR(10)&"К оплате: "&H34&CHAR(10)&"----------------------------------------------------------" -> #N/A
A35: 3 | B35: 45416 | C35: Максим рюкзак | D35: =VLOOKUP($C35,ТабКлиенты[[#All],[name]:[phone]],MATCH(D$1,ТабКлиенты[#Headers],0)-1,0) -> #N/A | E35: =VLOOKUP($C35,ТабАдрес[[#All],[Клиент]:[gps]],MATCH(E$1,ТабКлиенты[#Headers],0)-4,0) -> #N/A | F35: =VLOOKUP($C35,ТабАдрес[[#All],[Клиент]:[gps]],MATCH(F$1,ТабКлиенты[#Headers],0)-4,0) -> #N/A | H35: 0 | I35: 71 | K35: =A35&". "&C35&CHAR(10)&"Тел.: "&D35&CHAR(10)&"Адрес: "&E35&" ("&I35&")"&CHAR(10)&"https://yandex.ru/maps/?text="&REPLACE(F35,SEARCH(",",F35),2,"%2C")&CHAR(10)&"https://maps.google.com/?daddr="&REPLACE(F35,SEARCH(",",F35),2,"%2C")&CHAR(10)&"К оплате: "&H35&CHAR(10)&"----------------------------------------------------------" -> #N/A
A36: 4 | B36: 45416 | C36: Галина Шевченко 248 | D36: =VLOOKUP($C36,ТабКлиенты[[#All],[name]:[phone]],MATCH(D$1,ТабКлиенты[#Headers],0)-1,0) -> #N/A | E36: =VLOOKUP($C36,ТабАдрес[[#All],[Клиент]:[gps]],MATCH(E$1,ТабКлиенты[#Headers],0)-4,0) -> #N/A | F36: =VLOOKUP($C36,ТабАдрес[[#All],[Клиент]:[gps]],MATCH(F$1,ТабКлиенты[#Headers],0)-4,0) -> #N/A | H36: 0 | I36: 75 | K36: =A36&". "&C36&CHAR(10)&"Тел.: "&D36&CHAR(10)&"Адрес: "&E36&" ("&I36&")"&CHAR(10)&"https://yandex.ru/maps/?text="&REPLACE(F36,SEARCH(",",F36),2,"%2C")&CHAR(10)&"https://maps.google.com/?daddr="&REPLACE(F36,SEARCH(",",F36),2,"%2C")&CHAR(10)&"К оплате: "&H36&CHAR(10)&"----------------------------------------------------------" -> #N/A
A37: 5 | B37: 45416 | C37: Лариса Кирова | D37: =VLOOKUP($C37,ТабКлиенты[[#All],[name]:[phone]],MATCH(D$1,ТабКлиенты[#Headers],0)-1,0) -> #N/A | E37: =VLOOKUP($C37,ТабАдрес[[#All],[Клиент]:[gps]],MATCH(E$1,ТабКлиенты[#Headers],0)-4,0) -> #N/A | F37: =VLOOKUP($C37,ТабАдрес[[#All],[Клиент]:[gps]],MATCH(F$1,ТабКлиенты[#Headers],0)-4,0) -> #N/A | H37: 0 | I37: 76 | K37: =A37&". "&C37&CHAR(10)&"Тел.: "&D37&CHAR(10)&"Адрес: "&E37&" ("&I37&")"&CHAR(10)&"https://yandex.ru/maps/?text="&REPLACE(F37,SEARCH(",",F37),2,"%2C")&CHAR(10)&"https://maps.google.com/?daddr="&REPLACE(F37,SEARCH(",",F37),2,"%2C")&CHAR(10)&"К оплате: "&H37&CHAR(10)&"----------------------------------------------------------" -> #N/A
A38: 6 | B38: 45416 | C38: Елена Ларисына | D38: =VLOOKUP($C38,ТабКлиенты[[#All],[name]:[phone]],MATCH(D$1,ТабКлиенты[#Headers],0)-1,0) -> #N/A | E38: =VLOOKUP($C38,ТабАдрес[[#All],[Клиент]:[gps]],MATCH(E$1,ТабКлиенты[#Headers],0)-4,0) -> #N/A | F38: =VLOOKUP($C38,ТабАдрес[[#All],[Клиент]:[gps]],MATCH(F$1,ТабКлиенты[#Headers],0)-4,0) -> #N/A | H38: 1187 | I38: 78 | K38: =A38&". "&C38&CHAR(10)&"Тел.: "&D38&CHAR(10)&"Адрес: "&E38&" ("&I38&")"&CHAR(10)&"https://yandex.ru/maps/?text="&REPLACE(F38,SEARCH(",",F38),2,"%2C")&CHAR(10)&"https://maps.google.com/?daddr="&REPLACE(F38,SEARCH(",",F38),2,"%2C")&CHAR(10)&"К оплате: "&H38&CHAR(10)&"----------------------------------------------------------" -> #N/A
A39: 7 | B39: 45416 | C39: Митрофанов Евгений | D39: =VLOOKUP($C39,ТабКлиенты[[#All],[name]:[phone]],MATCH(D$1,ТабКлиенты[#Headers],0)-1,0) -> #N/A | E39: =VLOOKUP($C39,ТабАдрес[[#All],[Клиент]:[gps]],MATCH(E$1,ТабКлиенты[#Headers],0)-4,0) -> #N/A | F39: =VLOOKUP($C39,ТабАдрес[[#All],[Клиент]:[gps]],MATCH(F$1,ТабКлиенты[#Headers],0)-4,0) -> #N/A | H39: 0 | I39: 80 | K39: =A39&". "&C39&CHAR(10)&"Тел.: "&D39&CHAR(10)&"Адрес: "&E39&" ("&I39&")"&CHAR(10)&"https://yandex.ru/maps/?text="&REPLACE(F39,SEARCH(",",F39),2,"%2C")&CHAR(10)&"https://maps.google.com/?daddr="&REPLACE(F39,SEARCH(",",F39),2,"%2C")&CHAR(10)&"К оплате: "&H39&CHAR(10)&"----------------------------------------------------------" -> #N/A
A40: 8 | B40: 45416 | C40: Полинка | D40: =VLOOKUP($C40,ТабКлиенты[[#All],[name]:[phone]],MATCH(D$1,ТабКлиенты[#Headers],0)-1,0) -> #N/A | E40: =VLOOKUP($C40,ТабАдрес[[#All],[Клиент]:[gps]],MATCH(E$1,ТабКлиенты[#Headers],0)-4,0) -> #N/A | F40: =VLOOKUP($C40,ТабАдрес[[#All],[Клиент]:[gps]],MATCH(F$1,ТабКлиенты[#Headers],0)-4,0) -> #N/A | H40: -265 | I40: 1, 68 | K40: =A40&". "&C40&CHAR(10)&"Тел.: "&D40&CHAR(10)&"Адрес: "&E40&" ("&I40&")"&CHAR(10)&"https://yandex.ru/maps/?text="&REPLACE(F40,SEARCH(",",F40),2,"%2C")&CHAR(10)&"https://maps.google.com/?daddr="&REPLACE(F40,SEARCH(",",F40),2,"%2C")&CHAR(10)&"К оплате: "&H40&CHAR(10)&"----------------------------------------------------------" -> #N/A
...

Sheet Clients
A1: _id | B1: name | C1: percent | D1: accountManager | E1: __v | F1: createdAt | G1: updatedAt | H1: phone | I1: address | J1: gps | K1: contactPerson | L1: contactPersonPhone | M1: description | N1: email
A2: 68e24e5bb38906efee33845c | B2: Александр Космос | C2: 0 | D2: 68d297f82c15702607657e22 | E2: 0 | F2: 2025-10-05T10:54:19.203Z | G2: 2025-10-05T10:54:19.203Z | H2: +7 949 704-99-29 | I2: Б-р Шевченко 317 Грация | J2: 47.117993, 37.516302
A3: 68d297ff2c15702607657f13 | B3: Александр Радин | C3: 15 | D3: 68d297f82c15702607657e22 | E3: 0 | H3: +79497277100 | I3: Артема 132 | J3: 47.1085, 37.5599
A4: 68d297ff2c15702607657f2b | B4: Александра 50 лет СССР | C4: 15 | D4: 68d297f82c15702607657e22 | E4: 0 | H4: +79497167877 | I4: 50 лет СССР 20 кв 92 | J4: 47.1112, 37.5224
A5: 68f781c7adc63884d7a59e1c | B5: Алена Бахчик | C5: 0 | D5: 68d297f82c15702607657e22 | E5: 0 | F5: 2025-10-21T12:51:19.121Z | G5: 2025-10-21T12:51:19.121Z | H5: +79498485492 | M5: Бахчиванджи
A6: 68d298052c1570260765804f | B6: Алена Грация | C6: 15 | D6: 68d297f82c15702607657e22 | E6: 0 | H6: +79497049936 | I6: Шевченко 317 Грация | J6: 47.1179, 37.5163
A7: 68f783a8adc63884d7a59eb1 | B7: Алёна Чайка | C7: 0 | D7: 68d297f82c15702607657e22 | E7: 0 | F7: 2025-10-21T12:59:20.822Z | G7: 2025-10-21T12:59:20.823Z | H7: +79497200824
A8: 692ab7e17ab5058720faf6eb | B8: Алёна Шевченко, 295 | C8: 0 | D8: 68d297f82c15702607657e22 | E8: 0 | F8: 2025-11-29T09:07:45.082Z | G8: 2025-11-29T09:07:45.083Z | H8: +79498014741
A9: 6922f1c27ab5058720faed8a | B9: Алина стоматология Лекарь | C9: 0 | D9: 68d297f82c15702607657e22 | E9: 0 | F9: 2025-11-23T11:36:34.899Z | G9: 2025-11-23T11:36:34.900Z | H9: +79497141954
A10: 691c38ab7ab5058720fadf5a | B10: Анна Володарское шоссе | C10: 0 | D10: 68d297f82c15702607657e22 | E10: 0 | F10: 2025-11-18T09:13:15.507Z | G10: 2025-11-18T09:13:15.508Z | H10: +7 949 437 30 37
A11: 68d298002c15702607657f39 | B11: Анна соседка | C11: 15 | D11: 68d297f82c15702607657e22 | E11: 0 | H11: +79497105263 | I11: Казанцева 31 | J11: 47.1070, 37.5475
A12: 68f8bc256d77f5c8a72f9a14 | B12: Антонина Космос | C12: 0 | D12: 68d297f82c15702607657e22 | E12: 0 | F12: 2025-10-22T11:12:37.496Z | G12: 2025-10-22T11:12:37.496Z | H12: +7949
A13: 68d298012c15702607657f65 | B13: Аня Мирный | C13: 15 | D13: 68d297f82c15702607657e22 | E13: 0 | F13: 2025-10-22T10:55:32.942Z | G13: 2025-10-22T10:55:32.942Z | H13: +79497115237 | I13: пер Станционный 8 | J13: 47.1640, 37.5780
A14: 68d298012c15702607657f73 | B14: Валентина | C14: 15 | D14: 68d297f82c15702607657e22 | E14: 0 | H14: +79497095480 | I14: Трамвайный 10 | J14: 47.1044, 37.5233
A15: 68f8ba0d6d77f5c8a72f99d6 | B15: Валентина Кострова | C15: 0 | D15: 68d297f82c15702607657e22 | E15: 0 | F15: 2025-10-22T11:03:41.772Z | G15: 2025-10-22T11:03:41.772Z | H15: +79493008466
A16: 68d298032c15702607657fe1 | B16: Валентина Сычева | C16: 15 | D16: 68d297f82c15702607657e22 | E16: 0 | H16: +79497388231 | I16: Леваневского 58 | J16: 47.1007, 37.5310
A17: 68d298002c15702607657f33 | B17: Валерий СТО ОРИОН | C17: 15 | D17: 68d297f82c15702607657e22 | E17: 0 | H17: +79497398357 | I17: Макара Мазая 41
A18: 68d298022c15702607657fa3 | B18: Валерий Фагот | C18: 15 | D18: 68d297f82c15702607657e22 | E18: 0 | H18: +79497196221 | I18: Краснофлотская 132 | J18: 47.0917, 37.4968
A19: 68d298022c15702607657fb9 | B19: Вера Надеждына | C19: 15 | D19: 68d297f82c15702607657e22 | E19: 0 | H19: +79497169849 | I19: 17 рынок Грация | J19: 47.1122, 37.5146
A20: 68e253ebb38906efee338504 | B20: Вероника стоматолог | C20: 0 | D20: 68d297f82c15702607657e22 | E20: 0 | F20: 2025-10-05T11:18:03.087Z | G20: 2025-10-05T11:18:03.088Z | H20: +7 949 561-96-56 | I20: Пр. Ленина, 104 стоматология Лекарь | J20: 47.098132, 37.522480
A21: 68e649edd41346b9e28f3d38 | B21: Виктория | C21: 0 | D21: 68d297f82c15702607657e22 | E21: 0 | F21: 2025-10-08T11:24:29.036Z | G21: 2025-10-08T11:24:29.036Z | M21: Берберин, встречались на Башне
A22: 6904df630024359e23617ad7 | B22: Виктория Бахчиванджи | C22: 0 | D22: 68d297f82c15702607657e22 | E22: 0 | F22: 2025-10-31T16:10:11.618Z | G22: 2025-10-31T16:10:11.618Z | H22: +79490371889
A23: 691c42717ab5058720fadfc1 | B23: Виктория Башня/Энгельса | C23: 0 | D23: 68d297f82c15702607657e22 | E23: 0 | F23: 2025-11-18T09:54:57.525Z | G23: 2025-11-18T09:54:57.525Z | H23: +79497220585
A24: 68d298012c15702607657f89 | B24: Виктория БСМП | C24: 15 | D24: 68d297f82c15702607657e22 | E24: 0 | F24: 2025-10-22T11:13:49.727Z | G24: 2025-10-22T11:13:49.727Z | H24: +79497057045 | I24: Бахмутская 20 | J24: 47.1157, 37.5479
A25: 68d298032c15702607657fd3 | B25: Виктория Порт Сити | C25: 15 | D25: 68d297f82c15702607657e22 | E25: 0 | H25: +79497271852 | I25: Запорожское шоссе 2 | J25: 47.1176, 37.5083
A26: 68d298052c1570260765804d | B26: Виктория Страховка | C26: 15 | D26: 68d297f82c15702607657e22 | E26: 0 | H26: +79497163227 | I26: Артема 44 | J26: 47.0943, 37.5487
A27: 68d298032c15702607657fe3 | B27: Виктория Урицкого 93а | C27: 15 | D27: 68d297f82c15702607657e22 | E27: 0 | H27: +79497309448 | I27: Урицкого 93а | J27: 47.1238, 37.5116
A28: 68fca01e0024359e23617284 | B28: Виталий Тополиная, 12А | C28: 0 | D28: 68d297f82c15702607657e22 | E28: 0 | F28: 2025-10-25T10:02:06.347Z | G28: 2025-10-25T10:02:06.347Z | H28: +79494997775
A29: 68e5ff5fd41346b9e28f3d04 | B29: Виталий Черемушки | C29: 0 | D29: 68d297f82c15702607657e22 | E29: 0 | F29: 2025-10-08T06:06:23.114Z | G29: 2025-10-08T06:06:23.114Z | H29: +79498311537 | I29: Цибулько, 37 | K29: Виктория | L29: +7 949 831-15-38
A30: 68d298042c1570260765800b | B30: Власта консалтинг | C30: 15 | D30: 68d297f82c15702607657e22 | E30: 0 | H30: +79497377568 | I30: Металлургов 33 | J30: 47.0952, 37.5438
A31: 68d297fe2c15702607657ee9 | B31: Горжовская Ульяна NSP | C31: 15 | D31: 68d297f82c15702607657e22 | E31: 0
A32: 68d298002c15702607657f35 | B32: Даша Калифорния | C32: 15 | D32: 68d297f82c15702607657e22 | E32: 0 | H32: +79496248226 | I32: Шевченко 274 | J32: 47.1149, 37.5127
A33: 68ecf0d5a46150fa4106fcf4 | B33: Евгения | C33: 0 | D33: 68d297f82c15702607657e22 | E33: 0 | F33: 2025-10-13T12:30:13.302Z | G33: 2025-10-13T12:30:13.303Z | H33: +7 (949) 857-32-40 | I33: Металлургов 127 А | J33: 47.111534, 37.558841
A34: 68d298022c15702607657f93 | B34: Евгения Охотник | C34: 15 | D34: 68d297f82c15702607657e22 | E34: 0 | H34: +79497263506 | I34: Аэродромная 4 | J34: 47.1087, 37.5254
A35: 68d298052c15702607658033 | B35: Екатерина Металлургов 129 | C35: 15 | D35: 68d297f82c15702607657e22 | E35: 0 | H35: +79495256416 | I35: Металлургов 129 | J35: 47.1123, 37.5582
A36: 68d298022c15702607657fa5 | B36: Елена Индол | C36: 15 | D36: 68d297f82c15702607657e22 | E36: 0 | H36: +79497177018 | I36: Троицка 75, Рынок Юмовила | J36: 47.1121, 37.5156
A37: 692943757ab5058720faf3b2 | B37: Елена казначейство | C37: 0 | D37: 68d297f82c15702607657e22 | E37: 0 | F37: 2025-11-28T06:38:45.428Z | G37: 2025-11-28T06:38:45.429Z | H37: +79495149095
A38: 68d298062c15702607658057 | B38: Елена Ленина 87 | C38: 15 | D38: 68d297f82c15702607657e22 | E38: 0 | H38: +79495524078 | I38: Ленина 87 | J38: 47.0980, 37.5374
A39: 68d297fe2c15702607657ef3 | B39: Елена пер. Фруктовый | C39: 10 | D39: 68d297f82c15702607657e22 | E39: 0 | F39: 2025-10-13T13:03:52.574Z | G39: 2025-10-13T13:03:52.574Z | H39: +79497190408 | I39: Проектная 10 | J39: 47.1281, 37.5732
A40: 68d298032c15702607657fcf | B40: Елена сахарный диабет | C40: 15 | D40: 68d297f82c15702607657e22 | E40: 0 | F40: 2025-10-05T08:15:51.941Z | G40: 2025-10-05T08:15:51.941Z | H40: +79497183446 | I40: Металлургов 199 | J40: 47.1286, 37.5670
...

Sheet Адреса
A1: Клиент | B1: _id | C1: main | D1: customerId | E1: address | F1: gps | G1: description | H1: __v
A2: =VLOOKUP(ТабАдрес[[#This Row],[customerId]],ТабКлиенты[[#All],[_id]:[name]],2,0) -> Людмила Эдельвейс | B2: 68ee7e5778a38b35c0162bbc | C2: true | D2: 68d297ff2c15702607657f11 | E2: Металлургов 92 | F2: 47.1053, 37.5483 | H2: 0
A3: =VLOOKUP(ТабАдрес[[#This Row],[customerId]],ТабКлиенты[[#All],[_id]:[name]],2,0) -> Наталья Вельвет | B3: 68ee7e5778a38b35c0162bbf | C3: true | D3: 68d297fe2c15702607657ef7 | E3: Шевченко 285А | F3: 47.1169, 37.5258 | H3: 0
A4: =VLOOKUP(ТабАдрес[[#This Row],[customerId]],ТабКлиенты[[#All],[_id]:[name]],2,0) -> Наталья Школа 53 | B4: 68ee7e5778a38b35c0162bc1 | C4: true | D4: 68d297ff2c15702607657f1b | E4: Урицкого 77 | F4: 47.1228, 37.5167 | H4: 0
A5: =VLOOKUP(ТабАдрес[[#This Row],[customerId]],ТабКлиенты[[#All],[_id]:[name]],2,0) -> Наталья Зелинского | B5: 68ee7e5778a38b35c0162bc3 | C5: true | D5: 68d297ff2c15702607657f23 | E5: Зелинского 94 | F5: 47.1008, 37.5167 | H5: 0
A6: =VLOOKUP(ТабАдрес[[#This Row],[customerId]],ТабКлиенты[[#All],[_id]:[name]],2,0) -> Татьяна Торговая 100 | B6: 68ee7e5778a38b35c0162bba | C6: true | D6: 68d297ff2c15702607657f09 | E6: Торговая 100 | F6: 47.1034, 37.5633 | G6: Духи | H6: 0
A7: =VLOOKUP(ТабАдрес[[#This Row],[customerId]],ТабКлиенты[[#All],[_id]:[name]],2,0) -> Александра 50 лет СССР | B7: 68ee7e5778a38b35c0162bc5 | C7: true | D7: 68d297ff2c15702607657f2b | E7: 50 лет СССР 20 кв 92 | F7: 47.1112, 37.5224 | H7: 0
A8: =VLOOKUP(ТабАдрес[[#This Row],[customerId]],ТабКлиенты[[#All],[_id]:[name]],2,0) -> Наталья 60 лет СССР | B8: 68ee7e5778a38b35c0162bc7 | C8: true | D8: 68d298002c15702607657f2d | E8: 60 лет СССР 2Б | F8: 47.1178, 37.5121 | H8: 0
A9: =VLOOKUP(ТабАдрес[[#This Row],[customerId]],ТабКлиенты[[#All],[_id]:[name]],2,0) -> Валерий СТО ОРИОН | B9: 68ee7e5778a38b35c0162bc9 | C9: true | D9: 68d298002c15702607657f33 | E9: Макара Мазая 41 | H9: 0
A10: =VLOOKUP(ТабАдрес[[#This Row],[customerId]],ТабКлиенты[[#All],[_id]:[name]],2,0) -> Анна соседка | B10: 68ee7e5778a38b35c0162bcb | C10: true | D10: 68d298002c15702607657f39 | E10: Казанцева 31 | F10: 47.1070, 37.5475 | H10: 0
A11: =VLOOKUP(ТабАдрес[[#This Row],[customerId]],ТабКлиенты[[#All],[_id]:[name]],2,0) -> Даша Калифорния | B11: 68ee7e5778a38b35c0162bcd | C11: true | D11: 68d298002c15702607657f35 | E11: Шевченко 274 | F11: 47.1149, 37.5127 | H11: 0
A12: =VLOOKUP(ТабАдрес[[#This Row],[customerId]],ТабКлиенты[[#All],[_id]:[name]],2,0) -> Константин СТО Оптима | B12: 68ee7e5778a38b35c0162bcf | C12: true | D12: 68d298002c15702607657f3b | E12: Макара Мазая 41 | F12: 47.1361, 37.5817 | H12: 0
A13: =VLOOKUP(ТабАдрес[[#This Row],[customerId]],ТабКлиенты[[#All],[_id]:[name]],2,0) -> Татьяна Олимпийская 65 | B13: 68ee7e5778a38b35c0162bd1 | C13: true | D13: 68d297ff2c15702607657f25 | E13: Олимпийская 65, кв 28 | F13: 47.1086, 37.6706 | H13: 0
A14: =VLOOKUP(ТабАдрес[[#This Row],[customerId]],ТабКлиенты[[#All],[_id]:[name]],2,0) -> Лида корма | B14: 68ee7e5778a38b35c0162bd3 | C14: true | D14: 68d298002c15702607657f41 | E14: Шевченко 289А | F14: 47.1168, 37.5229 | H14: 0
A15: =VLOOKUP(ТабАдрес[[#This Row],[customerId]],ТабКлиенты[[#All],[_id]:[name]],2,0) -> Татьяна Леонидовна | B15: 68ee7e5778a38b35c0162bdb | C15: true | D15: 68d298002c15702607657f5b | E15: Шевченко 270 | F15: 47.1157, 37.5138 | H15: 0
A16: =VLOOKUP(ТабАдрес[[#This Row],[customerId]],ТабКлиенты[[#All],[_id]:[name]],2,0) -> Лакарова Татьяна | B16: 68ee7e5778a38b35c0162bdd | C16: true | D16: 68d298002c15702607657f5d | E16: Энгельса 28А | F16: 47.0964, 37.5459 | H16: 0
A17: =VLOOKUP(ТабАдрес[[#This Row],[customerId]],ТабКлиенты[[#All],[_id]:[name]],2,0) -> Любовь Виталий | B17: 68ee7e5778a38b35c0162bd9 | C17: true | D17: 68d298002c15702607657f53 | E17: Шевченко 325 | F17: 47.1193, 37.5172 | H17: 0
A18: =VLOOKUP(ТабАдрес[[#This Row],[customerId]],ТабКлиенты[[#All],[_id]:[name]],2,0) -> Светлана Федоровна | B18: 68ee7e5778a38b35c0162be1 | C18: true | D18: 68d298012c15702607657f67 | E18: Шопена 92 | F18: 47.1582, 37.6032 | H18: 0
A19: =VLOOKUP(ТабАдрес[[#This Row],[customerId]],ТабКлиенты[[#All],[_id]:[name]],2,0) -> Александр Радин | B19: 68ee7e5778a38b35c0162be5 | C19: true | D19: 68d297ff2c15702607657f13 | E19: Артема 132 | F19: 47.1085, 37.5599 | H19: 0
A20: =VLOOKUP(ТабАдрес[[#This Row],[customerId]],ТабКлиенты[[#All],[_id]:[name]],2,0) -> Лариса Терраспорт | B20: 68ee7e5778a38b35c0162be7 | C20: true | D20: 68d298012c15702607657f87 | E20: пер. Новгородский 41 | F20: 47.1100, 37.5242 | H20: 0
A21: =VLOOKUP(ТабАдрес[[#This Row],[customerId]],ТабКлиенты[[#All],[_id]:[name]],2,0) -> Лидия Живописная | B21: 68ee7e5778a38b35c0162be9 | C21: true | D21: 68d298012c15702607657f7b | E21: Живописная 7 зеленая крыша | F21: 47.1237, 37.5313 | H21: 0
... A72: =VLOOKUP(ТабАдрес[[#This Row],[customerId]],ТабКлиенты[[#All],[_id]:[name]],2,0) -> Олеся | B72: 68ee7e5778a38b35c0162c5c | C72: true | D72: 68e25c3bb38906efee33859d | E72: Урицкого, 107, подъезд 2 | F72: 47.124663, 37.508768 | H72: 0
A73: =VLOOKUP(ТабАдрес[[#This Row],[customerId]],ТабКлиенты[[#All],[_id]:[name]],2,0) -> Виталий Черемушки | B73: 68ee7e5778a38b35c0162c5a | C73: true | D73: 68e5ff5fd41346b9e28f3d04 | E73: Цибулько, 37 | H73: 0
A74: =VLOOKUP(ТабАдрес[[#This Row],[customerId]],ТабКлиенты[[#All],[_id]:[name]],2,0) -> Ольга Электромех. Колледж | B74: 68ee7e5778a38b35c0162c5e | C74: true | D74: 68e7a7f684f8b0568963190a | E74: Зелинского, 11 | F74: 47.089456, 37.516851 | H74: 0
A75: =VLOOKUP(ТабАдрес[[#This Row],[customerId]],ТабКлиенты[[#All],[_id]:[name]],2,0) -> Олеся Пугачева 23 | B75: 68ee7e5778a38b35c0162c60 | C75: true | D75: 68d298042c15702607657ff3 | E75: Пугачева 23 | F75: 47.1190, 37.5327 | H75: 0
A76: =VLOOKUP(ТабАдрес[[#This Row],[customerId]],ТабКлиенты[[#All],[_id]:[name]],2,0) -> Евгения | B76: 68ee7e5778a38b35c0162c64 | C76: true | D76: 68ecf0d5a46150fa4106fcf4 | E76: Металлургов 127 А | F76: 47.111534, 37.558841 | H76: 0
A77: =VLOOKUP(ТабАдрес[[#This Row],[customerId]],ТабКлиенты[[#All],[_id]:[name]],2,0) -> Софи | B77: 68ee7e5778a38b35c0162c66 | C77: true | D77: 68e802f184f8b05689631b30 | E77: пр. Строителей, 125 Обжора | F77: 47.099672, 37.524508 | H77: 0
A78: =VLOOKUP(ТабАдрес[[#This Row],[customerId]],ТабКлиенты[[#All],[_id]:[name]],2,0) -> Татьяна Константинова | B78: 68ee7e5778a38b35c0162c6e | C78: true | D78: 68e7ad8c84f8b05689631a5e | E78: рынок Калифорния | F78: 47.105156, 37.539071 | H78: 0
A79: =VLOOKUP(ТабАдрес[[#This Row],[customerId]],ТабКлиенты[[#All],[_id]:[name]],2,0) -> Татьяна Куприна 13 | B79: 68ee7e5778a38b35c0162c6c | C79: true | D79: 68d298032c15702607657ff1 | E79: Куприна 13 | F79: 47.1026, 37.5111 | H79: 0
A80: =VLOOKUP(ТабАдрес[[#This Row],[customerId]],ТабКлиенты[[#All],[_id]:[name]],2,0) -> Валерий Фагот | B80: 68ee7e5778a38b35c0162bff | C80: true | D80: 68d298022c15702607657fa3 | E80: Краснофлотская 132 | F80: 47.0917, 37.4968 | H80: 0
A81: =VLOOKUP(ТабАдрес[[#This Row],[customerId]],ТабКлиенты[[#All],[_id]:[name]],2,0) -> Ольга ЖД больница | B81: 68ee7e5778a38b35c0162c15 | C81: true | D81: 68d298032c15702607657fd7 | E81: Новороссийская 28, ЖД Больница | F81: 47.0718, 37.4881 | H81: 0
A82: =VLOOKUP(ТабАдрес[[#This Row],[customerId]],ТабКлиенты[[#All],[_id]:[name]],2,0) -> Руденко Юля | B82: 68f473d1bfaac217810d635c | C82: false | D82: 68d297fe2c15702607657edd | E82: Шевченко, 309 | H82: 0
A83: =VLOOKUP(ТабАдрес[[#This Row],[customerId]],ТабКлиенты[[#All],[_id]:[name]],2,0) -> Руденко Юля | B83: 68ee7e5778a38b35c0162bb8 | C83: true | D83: 68d297fe2c15702607657edd | E83: Мариуполь, Митрополитская, 60 | F83: 47.0999, 37.5500 | H83: 0
A84: =VLOOKUP(ТабАдрес[[#This Row],[customerId]],ТабКлиенты[[#All],[_id]:[name]],2,0) -> Оксана 17 Цветы | B84: 68ee7e5778a38b35c0162be3 | C84: true | D84: 68d298012c15702607657f63 | E84: Троицкая 46 | F84: 47.1119, 37.5147 | H84: 0
A85: =VLOOKUP(ТабАдрес[[#This Row],[customerId]],ТабКлиенты[[#All],[_id]:[name]],2,0) -> Оксана 17 Цветы | B85: 68f48d1308b99d02255ce3e1 | C85: false | D85: 68d298012c15702607657f63 | E85: Шевченко, 295 | F85: 47.116923, 37.522235 | G85: Киоск Цветы | H85: 0
A86: =VLOOKUP(ТабАдрес[[#This Row],[customerId]],ТабКлиенты[[#All],[_id]:[name]],2,0) -> Татьяна Индол | B86: 68f618f9adc63884d7a59be3 | C86: true | D86: 68f618f8adc63884d7a59be1 | E86: Энгельса, 53 | H86: 0
A87: =VLOOKUP(ТабАдрес[[#This Row],[customerId]],ТабКлиенты[[#All],[_id]:[name]],2,0) -> Светлана Кулаки | B87: 68ee7e5778a38b35c0162bef | C87: true | D87: 68d298012c15702607657f8b | E87: Ткаченко Петренко 3 | F87: 47.0853, 37.5071 | H87: 0
A88: =VLOOKUP(ТабАдрес[[#This Row],[customerId]],ТабКлиенты[[#All],[_id]:[name]],2,0) -> Светлана Кулаки | B88: 68f7801aadc63884d7a59d78 | C88: false | D88: 68d298012c15702607657f8b | E88: Лавицкого, 7 | F88: 47.087776, 37.522944 | G88: Школа №60 | H88: 0
A89: =VLOOKUP(ТабАдрес[[#This Row],[customerId]],ТабКлиенты[[#All],[_id]:[name]],2,0) -> Надежда Витамины | B89: 68f78087adc63884d7a59dd9 | C89: false | D89: 68d298002c15702607657f47 | E89: Строителей, 102 | F89: 47.100776, 37.522477 | G89: дет. сад. №125 | H89: 0
A90: =VLOOKUP(ТабАдрес[[#This Row],[customerId]],ТабКлиенты[[#All],[_id]:[name]],2,0) -> Надежда Витамины | B90: 68ee7e5778a38b35c0162bd5 | C90: true | D90: 68d298002c15702607657f47 | E90: пер. Ейский 9 | F90: 47.0898, 37.5062 | H90: 0
...

Sheet Карта ESSENS
A1: Сайт ESSENS | G1: Остатки
A2: Женские | C2: Мужские | Q2: ESSENS, NOIR by ESSENS Lost Cherry 50мл, 1233346389
A3: Парфюм | B3: Пробник | C3: Парфюм | D3: Пробник | G3: Женские | H3: Мужские | I3: Презентер1 | J3: Презентер2 | K3: Пробники | Q3: ESSENS, Noir Духи - №2, 0004eln02s
A4: w102 | B4: Unique 06 | C4: m001 | D4: Petronas | G4: NOIR by ESSENS Lost Cherry 50мл | H4: m003 | I4: m003 | J4: m003 | K4: m041 | Q4: ESSENS, Духи для женщин w111, 000w11150
A5: w104 | B5: Unique eu05 | C5: m003 | D5: m001 | G5: Noir Духи - №2 | H5: m007 | I5: m007 | J5: m007 | K5: m042 | Q5: ESSENS, Духи для женщин w114, 000w11450
A6: w105 | B6: w101 | C6: m007 | D6: m003 | G6: w102 | H6: m008 | I6: m008 | J6: m008 | K6: m043 | Q6: ESSENS, Духи для женщин w116, 000w11650
A7: w106 | B7: w102 | C7: m008 | D7: m007 | G7: w107 | H7: m015 | I7: m014 | J7: m014 | K7: m044 | Q7: ESSENS, Духи для женщин w124, 000w12450
A8: w107 | B8: w104 | C8: m013 | D8: m008 | G8: w111 | H8: m024 | I8: m015 | J8: m015 | K8: m045 | Q8: ESSENS, Духи для женщин w142, 000w14250
A9: w111 | B9: w105 | C9: m014 | D9: m013 | G9: w114 | H9: m025 | I9: m016 | J9: m016 | K9: m901 | Q9: ESSENS, Духи для женщин w144, 000w14450
A10: w113 | B10: w106 | C10: m015 | D10: m014 | G10: w116 | H10: m029 | I10: m017 | J10: m017 | K10: w191 | Q10: ESSENS, Духи для женщин w150, 000w15050
A11: w114 | B11: w107 | C11: m016 | D11: m015 | G11: w124 | H11: m035 | I11: m018 | J11: m018 | K11: w192 | Q11: ESSENS, Духи для женщин w151, 000w15150
A12: w115 | B12: w110 | C12: m017 | D12: m016 | G12: w137 | H12: m037 | I12: m024 | J12: m024 | K12: w183 | Q12: ESSENS, Духи для женщин w156, 000w15650
A13: w116 | B13: w111 | C13: m018 | D13: m017 | G13: w141 | H13: m038 | I13: m025 | J13: m025 | K13: w193 | Q13: ESSENS, Духи для женщин w159n, 000w15950n
A14: w117 | B14: w112 | C14: m022 | D14: m018 | G14: w142 | H14: m043 | I14: m027 | J14: m027 | K14: w903 | Q14: ESSENS, Духи для женщин w162, 000w16250
... A16: w124 | B16: w114 | C16: m025 | D16: m020 | G16: w148 | H16: m901 | I16: m029 | J16: m029 | K16: w184 | Q16: ESSENS, Духи для женщин w172, 000w17250
A17: w127 | B17: w116 | C17: m027 | D17: m021 | G17: w150 | I17: m034 | J17: m034 | K17: w185 | Q17: ESSENS, Духи для женщин w173, 000w17350
A18: w130 | B18: w117 | C18: m028 | D18: m022 | G18: w151 | I18: m035 | J18: m035 | K18: w189 | Q18: ESSENS, Духи для женщин w176, 000w17650
A19: w137 | B19: w118 | C19: m029 | D19: m023 | G19: w156 | I19: m036 | J19: m036 | K19: w902 | Q19: ESSENS, Духи для женщин w177, 000w17750
A20: w141 | B20: w124 | C20: m034 | D20: m024 | G20: w159n | I20: m037 | J20: m037 | K20: w186 | Q20: ESSENS, Духи для женщин w179, 000w17950
A21: w142 | B21: w126 | C21: m035 | D21: m025 | G21: w162 | I21: m038 | J21: m038 | K21: w194 | Q21: ESSENS, Духи для женщин w180, 000w18050
A22: w144 | B22: w127 | C22: m036 | D22: m026 | G22: w171 | I22: m039 | J22: m039 | K22: w187 | Q22: ESSENS, Духи для женщин w182, 000w18250
A23: w148 | B23: w130 | C23: m037 | D23: m027 | G23: w172 | I23: m040 | J23: m040 | K23: w162 | Q23: ESSENS, Духи для женщин w183, 000w18350
A24: w150 | B24: w132 | C24: m038 | D24: m028 | G24: w173 | I24: w102 | J24: w102 | K24: w002 | Q24: ESSENS, Духи для женщин w185, 000w18550
A25: w151 | B25: w137 | C25: m039 | D25: m029 | G25: w176 | I25: w104 | J25: w104 | K25: w006 | Q25: ESSENS, Духи для женщин w186, 000w18650
A26: w153 | B26: w141 | C26: m040 | D26: m030 | G26: w177 | I26: w105 | J26: w105 | Q26: ESSENS, Духи для женщин w188, 000w18850
A27: w155 | B27: w142 | C27: m041 | D27: m031 | G27: w179 | I27: w106 | J27: w106 | Q27: ESSENS, Духи для женщин w190, 000w19050
A28: w156 | B28: w144 | C28: m042 | D28: m032 | G28: w180 | I28: w107 | J28: w107 | Q28: ESSENS, Духи для женщин w191, 000w19150
A29: w157 | B29: w146 | C29: m043 | D29: m033 | G29: w182 | I29: w111 | J29: w111 | Q29: ESSENS, Духи для женщин w192, 000w19250
A30: w158 | B30: w147 | C30: m044 | D30: m034 | G30: w183 | I30: w114 | J30: w114 | Q30: ESSENS, Духи для женщин w193, 000w19350
A31: w159n | B31: w148 | C31: m045 | D31: m035 | G31: w185 | I31: w116 | J31: w116 | Q31: ESSENS, Духи для мужчин m007, 000m00750
A32: w163 | B32: w149 | C32: m901 | D32: m036 | G32: w186 | I32: w117 | J32: w117 | Q32: ESSENS, Духи для мужчин m008, 000m00850
A33: w166 | B33: w150 | C33: m902 | D33: m037 | G33: w188 | I33: w118 | J33: w118 | Q33: ESSENS, Духи для мужчин m015, 000m01550
A34: w171 | B34: w151 | D34: m038 | G34: w190 | I34: w124 | J34: w124 | Q34: ESSENS, Духи для мужчин m029, 000m02950
A35: w173 | B35: w152 | D35: m039 | G35: w191 | I35: w127 | J35: w127 | Q35: ESSENS, Духи для мужчин m035, 000m03550
A36: w178 | B36: w153 | D36: m040 | G36: w192 | I36: w130 | J36: w130 | Q36: ESSENS, Духи для мужчин m037, 000m03750
A37: w179 | B37: w154 | D37: m041 | G37: w193 | I37: w137 | J37: w137 | Q37: ESSENS, Духи для мужчин m038, 000m03850
A38: w181 | B38: w155 | D38: m042 | G38: w902 | I38: w141 | J38: w141 | Q38: ESSENS, Духи для мужчин m043, 000m04350
A39: w182 | B39: w156 | D39: m043 | G39: w903 | I39: w142 | J39: w142 | Q39: ESSENS, Духи для мужчин m044, 000m04450
A40: w183 | B40: w157 | D40: m044 | I40: w144 | J40: w144 | Q40: ESSENS, Набор парфюмерный женский Chance Eau Tendre №182, 1395837779
A41: w184 | B41: w158 | D41: m045 | I41: w148 | J41: w148 | Q41: ESSENS, Набор парфюмерный женский по мотивам J'adore №118, 1271446882
...

Sheet СводнаяДоходы
A2: Остатки | C2: В пути
A3: Витамины | B3: =SUMIFS(Journal!$U:$U,Journal!$T:$T,"",Journal!$G:$G,A3) -> -503103.25 | C3: =SUMIFS(Journal!$U:$U,Journal!$T:$T,"",Journal!$G:$G,$A3,Journal!$D:$D,"<>Доставлен") -> -118761.36
A4: Спортпит | B4: =SUMIFS(Journal!$U:$U,Journal!$T:$T,"",Journal!$G:$G,A4) -> -33152.913 | C4: =SUMIFS(Journal!$U:$U,Journal!$T:$T,"",Journal!$G:$G,$A4,Journal!$D:$D,"<>Доставлен") -> 0
A5: Косметика | B5: =SUMIFS(Journal!$U:$U,Journal!$T:$T,"",Journal!$G:$G,A5) -> -139327.62 | C5: =SUMIFS(Journal!$U:$U,Journal!$T:$T,"",Journal!$G:$G,$A5,Journal!$D:$D,"<>Доставлен") -> -7656.3671
A6: Парфюм | B6: =SUMIFS(Journal!$U:$U,Journal!$T:$T,"",Journal!$G:$G,A6) -> -94394.21 | C6: =SUMIFS(Journal!$U:$U,Journal!$T:$T,"",Journal!$G:$G,$A6,Journal!$D:$D,"<>Доставлен") -> 0
A7: Итого: | B7: =SUM(B3:B6) -> -769977.99 | C7: =SUM(C3:C6) -> -126417.73
D9: Итого доход | H9: Наценка
A10: Названия строк | B10: Итого затрат RUB | C10: Итого продаж | D10: Витамины | E10: Спортпит | F10: Косметика | G10: Парфюм | I10: Всего
A11: 2022 07 | B11: 12475.57 | C11: =SUMIF(Journal!$T:$T,A11,Journal!$Q:$Q) -> 0 | D11: =SUMIFS(Journal!$U:$U,Journal!$T:$T,$A11,Journal!$G:$G,$D$10) -> 0 | E11: =SUMIFS(Journal!$U:$U,Journal!$T:$T,$A11,Journal!$G:$G,$E$10) -> 0 | F11: =SUMIFS(Journal!$U:$U,Journal!$T:$T,$A11,Journal!$G:$G,$F$10) -> 0 | I11: =SUM(D11:F11) -> 0
A12: 2022 08 | B12: 36480.995 | C12: =SUMIF(Journal!$T:$T,A12,Journal!$Q:$Q) -> 21400 | D12: =SUMIFS(Journal!$U:$U,Journal!$T:$T,$A12,Journal!$G:$G,$D$10) -> 8820.1844 | E12: =SUMIFS(Journal!$U:$U,Journal!$T:$T,$A12,Journal!$G:$G,$E$10) -> 0 | F12: =SUMIFS(Journal!$U:$U,Journal!$T:$T,$A12,Journal!$G:$G,$F$10) -> 546.73282 | G12: =SUMIFS(Journal!$U:$U,Journal!$T:$T,$A12,Journal!$G:$G,$G$10) -> 0 | H12: =I12/(C12-I12) -> 0.77843038 | I12: =SUM(D12:G12) -> 9366.9172
A13: 2022 09 | B13: 23308.388 | C13: =SUMIF(Journal!$T:$T,A13,Journal!$Q:$Q) -> 50902.59 | D13: =SUMIFS(Journal!$U:$U,Journal!$T:$T,$A13,Journal!$G:$G,$D$10) -> 20454.989 | E13: =SUMIFS(Journal!$U:$U,Journal!$T:$T,$A13,Journal!$G:$G,$E$10) -> 4536 | F13: =SUMIFS(Journal!$U:$U,Journal!$T:$T,$A13,Journal!$G:$G,$F$10) -> 495.37889 | G13: =SUMIFS(Journal!$U:$U,Journal!$T:$T,$A13,Journal!$G:$G,$G$10) -> 0 | H13: =I13/(C13-I13) -> 1.0027599 | I13: =SUM(D13:G13) -> 25486.368
A14: 2022 10 | B14: 56582.405 | C14: =SUMIF(Journal!$T:$T,A14,Journal!$Q:$Q) -> 53127.22 | D14: =SUMIFS(Journal!$U:$U,Journal!$T:$T,$A14,Journal!$G:$G,$D$10) -> 27582.366 | E14: =SUMIFS(Journal!$U:$U,Journal!$T:$T,$A14,Journal!$G:$G,$E$10) -> 1343.2794 | F14: =SUMIFS(Journal!$U:$U,Journal!$T:$T,$A14,Journal!$G:$G,$F$10) -> 131.15024 | G14: =SUMIFS(Journal!$U:$U,Journal!$T:$T,$A14,Journal!$G:$G,$G$10) -> 0 | H14: =I14/(C14-I14) -> 1.2071576 | I14: =SUM(D14:G14) -> 29056.795
A15: 2022 11 | B15: 203204.95 | C15: =SUMIF(Journal!$T:$T,A15,Journal!$Q:$Q) -> 136450 | D15: =SUMIFS(Journal!$U:$U,Journal!$T:$T,$A15,Journal!$G:$G,$D$10) -> 63310.407 | E15: =SUMIFS(Journal!$U:$U,Journal!$T:$T,$A15,Journal!$G:$G,$E$10) -> 4271.2409 | F15: =SUMIFS(Journal!$U:$U,Journal!$T:$T,$A15,Journal!$G:$G,$F$10) -> 4328.7095 | G15: =SUMIFS(Journal!$U:$U,Journal!$T:$T,$A15,Journal!$G:$G,$G$10) -> 0 | H15: =I15/(C15-I15) -> 1.1142045 | I15: =SUM(D15:G15) -> 71910.358
A16: 2022 12 | B16: 137714.47 | C16: =SUMIF(Journal!$T:$T,A16,Journal!$Q:$Q) -> 129424.33 | D16: =SUMIFS(Journal!$U:$U,Journal!$T:$T,$A16,Journal!$G:$G,$D$10) -> 47648.29 | E16: =SUMIFS(Journal!$U:$U,Journal!$T:$T,$A16,Journal!$G:$G,$E$10) -> 1709.216 | F16: =SUMIFS(Journal!$U:$U,Journal!$T:$T,$A16,Journal!$G:$G,$F$10) -> 2311.3849 | G16: =SUMIFS(Journal!$U:$U,Journal!$T:$T,$A16,Journal!$G:$G,$G$10) -> 0 | H16: =I16/(C16-I16) -> 0.66450514 | I16: =SUM(D16:G16) -> 51668.891
A17: 2023 01 | B17: 218003.17 | C17: =SUMIF(Journal!$T:$T,A17,Journal!$Q:$Q) -> 258998.14 | D17: =SUMIFS(Journal!$U:$U,Journal!$T:$T,$A17,Journal!$G:$G,$D$10) -> 85277.333 | E17: =SUMIFS(Journal!$U:$U,Journal!$T:$T,$A17,Journal!$G:$G,$E$10) -> 25338.22 | F17: =SUMIFS(Journal!$U:$U,Journal!$T:$T,$A17,Journal!$G:$G,$F$10) -> 6806.7827 | G17: =SUMIFS(Journal!$U:$U,Journal!$T:$T,$A17,Journal!$G:$G,$G$10) -> 0 | H17: =I17/(C17-I17) -> 0.82939552 | I17: =SUM(D17:G17) -> 117422.34
A18: 2023 02 | B18: 250819.23 | C18: =SUMIF(Journal!$T:$T,A18,Journal!$Q:$Q) -> 244757.31 | D18: =SUMIFS(Journal!$U:$U,Journal!$T:$T,$A18,Journal!$G:$G,$D$10) -> 77435.301 | E18: =SUMIFS(Journal!$U:$U,Journal!$T:$T,$A18,Journal!$G:$G,$E$10) -> 24839.476 | F18: =SUMIFS(Journal!$U:$U,Journal!$T:$T,$A18,Journal!$G:$G,$F$10) -> 3137.0332 | G18: =SUMIFS(Journal!$U:$U,Journal!$T:$T,$A18,Journal!$G:$G,$G$10) -> 0 | H18: =I18/(C18-I18) -> 0.75647804 | I18: =SUM(D18:G18) -> 105411.81
A19: 2023 03 | B19: 211470.11 | C19: =SUMIF(Journal!$T:$T,A19,Journal!$Q:$Q) -> 397722.32 | D19: =SUMIFS(Journal!$U:$U,Journal!$T:$T,$A19,Journal!$G:$G,$D$10) -> 147314.43 | E19: =SUMIFS(Journal!$U:$U,Journal!$T:$T,$A19,Journal!$G:$G,$E$10) -> 18476.175 | F19: =SUMIFS(Journal!$U:$U,Journal!$T:$T,$A19,Journal!$G:$G,$F$10) -> 13217.423 | G19: =SUMIFS(Journal!$U:$U,Journal!$T:$T,$A19,Journal!$G:$G,$G$10) -> 0 | H19: =I19/(C19-I19) -> 0.818456 | I19: =SUM(D19:G19) -> 179008.03
A20: 2023 04 | B20: 201384.13 | C20: =SUMIF(Journal!$T:$T,A20,Journal!$Q:$Q) -> 218200.4 | D20: =SUMIFS(Journal!$U:$U,Journal!$T:$T,$A20,Journal!$G:$G,$D$10) -> 58999.878 | E20: =SUMIFS(Journal!$U:$U,Journal!$T:$T,$A20,Journal!$G:$G,$E$10) -> 28237.463 | F20: =SUMIFS(Journal!$U:$U,Journal!$T:$T,$A20,Journal!$G:$G,$F$10) -> 4980.6627 | G20: =SUMIFS(Journal!$U:$U,Journal!$T:$T,$A20,Journal!$G:$G,$G$10) -> 0 | H20: =I20/(C20-I20) -> 0.73199119 | I20: =SUM(D20:G20) -> 92218.004
A21: 2023 05 | B21: 202220.42 | C21: =SUMIF(Journal!$T:$T,A21,Journal!$Q:$Q) -> 187411.49 | D21: =SUMIFS(Journal!$U:$U,Journal!$T:$T,$A21,Journal!$G:$G,$D$10) -> 55273.41 | E21: =SUMIFS(Journal!$U:$U,Journal!$T:$T,$A21,Journal!$G:$G,$E$10) -> 15291.584 | F21: =SUMIFS(Journal!$U:$U,Journal!$T:$T,$A21,Journal!$G:$G,$F$10) -> 1458.2754 | G21: =SUMIFS(Journal!$U:$U,Journal!$T:$T,$A21,Journal!$G:$G,$G$10) -> 0 | H21: =I21/(C21-I21) -> 0.62418217 | I21: =SUM(D21:G21) -> 72023.269
A22: 2023 06 | B22: 175586.89 | C22: =SUMIF(Journal!$T:$T,A22,Journal!$Q:$Q) -> 244424.19 | D22: =SUMIFS(Journal!$U:$U,Journal!$T:$T,$A22,Journal!$G:$G,$D$10) -> 65617.326 | E22: =SUMIFS(Journal!$U:$U,Journal!$T:$T,$A22,Journal!$G:$G,$E$10) -> 11996.515 | F22: =SUMIFS(Journal!$U:$U,Journal!$T:$T,$A22,Journal!$G:$G,$F$10) -> 3431.8755 | G22: =SUMIFS(Journal!$U:$U,Journal!$T:$T,$A22,Journal!$G:$G,$G$10) -> 0 | H22: =I22/(C22-I22) -> 0.49606117 | I22: =SUM(D22:G22) -> 81045.716
A23: 2023 07 | B23: 138647.7 | C23: =SUMIF(Journal!$T:$T,A23,Journal!$Q:$Q) -> 264715.82 | D23: =SUMIFS(Journal!$U:$U,Journal!$T:$T,$A23,Journal!$G:$G,$D$10) -> 59673.983 | E23: =SUMIFS(Journal!$U:$U,Journal!$T:$T,$A23,Journal!$G:$G,$E$10) -> 27240.619 | F23: =SUMIFS(Journal!$U:$U,Journal!$T:$T,$A23,Journal!$G:$G,$F$10) -> 861.54395 | G23: =SUMIFS(Journal!$U:$U,Journal!$T:$T,$A23,Journal!$G:$G,$G$10) -> 0 | H23: =I23/(C23-I23) -> 0.49607951 | I23: =SUM(D23:G23) -> 87776.146
